Workbook

Sheet Questions 1, 2
B1: 2021 | C1: 2022 | D1: 2023 | E1: Variation 2021/2022 | F1: Variation 2022/2023
A2: Fonds de roulement (FRNG)
A3: (+)Ressources stables (RS) | B3: ='Question 5 Bilan'!J18+'Question 5 Bilan'!J27 -> 1379976 | C3: ='Question 5 Bilan'!I18+'Question 5 Bilan'!I27 -> 1325841 | D3: ='Question 5 Bilan'!H18+'Question 5 Bilan'!H27 -> 1194962 | E3: =(C3-B3)/B3 -> -0.039228943 | F3: =(D3-C3)/C3 -> -0.098713948
A4: (-) Emplois stables (ES) | B4: ='Question 5 Bilan'!F24 -> 1203175 | C4: ='Question 5 Bilan'!E24 -> 1014261 | D4: ='Question 5 Bilan'!D24 -> 989066 | E4: =(C4-B4)/B4 -> -0.1570129 | F4: =(D4-C4)/C4 -> -0.024840746
A5: (= ) FRNG | B5: =B3-B4 -> 176801 | C5: =C3-C4 -> 311580 | D5: =D3-D4 -> 205896 | E5: =(C5-B5)/B5 -> 0.76232035 | F5: =(D5-C5)/C5 -> -0.33918737
A7: Besoin fonds de roulement (BFR)
A8: (+) Actif circulant (AC) | B8: ='Question 5 Bilan'!F37-'Question 5 Bilan'!F36 -> 1009011 | C8: ='Question 5 Bilan'!E37-'Question 5 Bilan'!E36 -> 977309 | D8: ='Question 5 Bilan'!D37-'Question 5 Bilan'!D36 -> 993787 | E8: =(C8-B8)/B8 -> -0.031418884 | F8: =(D8-C8)/C8 -> 0.016860584
A9: (-) Passif circulant (PC) | B9: ='Question 5 Bilan'!J35 -> 837104 | C9: ='Question 5 Bilan'!I35 -> 786993 | D9: ='Question 5 Bilan'!H35 -> 796898 | E9: =(C9-B9)/B9 -> -0.059862335 | F9: =(D9-C9)/C9 -> 0.012585881
A10: (= ) BFR | B10: =B8-B9 -> 171907 | C10: =C8-C9 -> 190316 | D10: =D8-D9 -> 196889 | E10: =(C10-B10)/B10 -> 0.10708697 | F10: =(D10-C10)/C10 -> 0.034537296
A12: Trésorerie nette (TN)
A13: (+) Fonds de roulement | B13: =B5 -> 176801 | C13: =C5 -> 311580 | D13: =D5 -> 205896 | E13: =(C13-B13)/B13 -> 0.76232035 | F13: =(D13-C13)/C13 -> -0.33918737
A14: (-) BFR | B14: =B10 -> 171907 | C14: =C10 -> 190316 | D14: =D10 -> 196889 | E14: =(C14-B14)/B14 -> 0.10708697 | F14: =(D14-C14)/C14 -> 0.034537296
A15: (= ) TN | B15: =B13-B14 -> 4894 | C15: =C13-C14 -> 121264 | D15: =D13-D14 -> 9007 | E15: =(C15-B15)/B15 -> 23.778096 | F15: =(D15-C15)/C15 -> -0.92572404
A17: Capacité d'autofinancement
A18: (+) Résultat net de l'ensemble consolidé | B18: 27808 | C18: 27227 | D18: 24717 | E18: =(C18-B18)/B18 -> -0.020893268 | F18: =(D18-C18)/C18 -> -0.092187902
A20: (+) Dotation aux amortissements
A21: Dotations/Reprises provisions pour risques et charges | B21: 1261 | C21: -281 | D21: -1737 | E21: =(C21-B21)/B21 -> -1.222839 | F21: =(D21-C21)/C21 -> 5.1814947
A22: Dotations/Reprises provisions immobilisations financières et VMP | B22: 0 | C22: 1540 | D22: 2082 | F22: =(D22-C22)/C22 -> 0.35194805
A23: Dotations/Reprises Provisions pour Impôt | B23: 1291 | C23: -376 | D23: 3751 | E23: =(C23-B23)/B23 -> -1.2912471 | F23: =(D23-C23)/C23 -> -10.976064
A25: (= ) CAF | B25: =B18+B21+B22+B23 -> 30360 | C25: =C18+C21+C22+C23 -> 28110 | D25: =D18+D21+D22+D23 -> 28813 | E25: =(C25-B25)/B25 -> -0.074110672 | F25: =(D25-C25)/C25 -> 0.025008894

Sheet Ratios
B1: 2021 | C1: 2022 | D1: 2023
A2: Résultat net | B2: 57121 | C2: 35429 | D2: 14488 | F2: Les résultats sont en milliers d'euros (k€)
A3: Total actifs/Total passif (AE) | B3: ='Question 5 Bilan'!F40 -> 2217080 | C3: ='Question 5 Bilan'!E40 -> 2112834 | D3: ='Question 5 Bilan'!D40 -> 1991860
A4: Capitaux propres | B4: ='Question 5 Bilan'!J18 -> 739784 | C4: ='Question 5 Bilan'!I18 -> 852406 | D4: ='Question 5 Bilan'!H18 -> 774456
A5: Chiffre d'affaires (HT) | B5: 2163616 | C5: 2202613 | D5: 2406221
A6: Chiffre d'affaires TTC (20%) | B6: =1.2*B5 -> 2596339.2 | C6: =1.2*C5 -> 2643135.6 | D6: =1.2*D5 -> 2887465.2
A7: Créances client | B7: 311982 | C7: 343422 | D7: 305044
A8: Durée de l'exercice (jours) | B8: 360 | C8: 360 | D8: 360
A9: Stocks | B9: 677057 | C9: 618296 | D9: 668080
A10: Achats consommés | B10: -1127709 | C10: -1217888 | D10: -1304793 | E10: <----------------- | F10: Les achats concernés sont calculés comme la somme des achats en stock et des achats consommés.
A11: Achats concernés | B11: =B9-B10 -> 1804766 | C11: =C9-C10 -> 1836184 | D11: =D9-D10 -> 1972873
A12: Achats concernés (TTC) | B12: =1.2*B11 -> 2165719.2 | C12: =1.2*C11 -> 2203420.8 | D12: =1.2*D11 -> 2367447.6
A13: Dette fournisseurs | B13: 653555 | C13: 690571 | D13: 687143
A14: Charges externes | B14: 441883 | C14: 491469 | D14: 536626
A15: Charges externes (TTC) | B15: =1.2*B14 -> 530259.6 | C15: =1.2*C14 -> 589762.8 | D15: =1.2*D14 -> 643951.2
A16: Dette | B16: 120230 | C16: 113574 | D16: 87708
A17: Impôts et taxes | B17: 10893 | C17: 39987 | D17: 18460
A18: Charges de personnels | B18: 477361 | C18: 478105 | D18: 512374
A19: Résultat d'exploitation | B19: -2031 | C19: -2120 | D19: -1462
A20: Emplois stables | B20: 1203175 | C20: 1014261 | D20: 989066
A21: Dette financière | B21: 496268 | C21: 338125 | D21: 296947
A22: Disponibilités | B22: 4634 | C22: 121104 | D22: 8988
A23: Charges financières | B23: 2097 | C23: 3016 | D23: 4634
A25: La marge brute | B25: =B19/B20 -> -0.0016880337 | C25: =C19/C20 -> -0.0020901918 | D25: =D19/D20 -> -0.0014781622
A28: Rentabilité économique (ROA) | B28: =B2/B3 -> 0.025764068 | C28: =C2/C3 -> 0.016768473 | D28: =D2/D3 -> 0.0072736036
A29: Rentabilité fiancière (ROE) | B29: =B2/B4 -> 0.077213078 | C29: =C2/C4 -> 0.041563527 | D29: =D2/D4 -> 0.018707325
A30: Rentabilité d'exploitation (TMN) | B30: =B2/B5 -> 0.026400711 | C30: =C2/C5 -> 0.016084986 | D30: =D2/D5 -> 0.0060210596
A32: Délai client (en jour) | B32: =(B7*B8)/B6 -> 43.258416 | C32: =(C7*C8)/C6 -> 46.774717 | D32: =(D7*D8)/D6 -> 38.031918
A33: Délai stocks (en jour) | B33: =(B9*B8)/B12 -> 112.54484 | C33: =(C9*C8)/C12 -> 101.01863 | D33: =(D9*D8)/D12 -> 101.58991
A34: Délai fournisseurs (en jour) | B34: =(B13*B8)/(B12+B15) -> 87.270642 | C34: =(C13*C8)/(C12+C15) -> 89.004375 | D34: =(D13*D8)/(D12+D15) -> 82.145042
A36: Valeur ajoutée (VA) | B36: 42923 | C36: 44373 | D36: 43502
A37: VA/CA | B37: =B36/B5 -> 0.019838548 | C37: =C36/C5 -> 0.020145618 | D37: =D36/D5 -> 0.018078971
A38: EBE | B38: =8822-10853 -> -2031 | C38: -2121 | D38: -1462
A40: Total de l'actif moyen | B40: =618529 -> 618529 | C40: 623720 | D40: 614674
A41: Marge nette | B41: =B2/B5 -> 0.026400711 | C41: =C2/C5 -> 0.016084986 | D41: =D2/D5 -> 0.0060210596
A42: Rotation de l'actif | B42: =B5/B40 -> 3.4980025 | C42: =C5/C40 -> 3.5314131 | D42: =D5/D40 -> 3.9146295
A43: Levier financier | B43: =B29/B28 -> 2.9969288 | C43: =C29/C28 -> 2.478671 | D43: =D29/D28 -> 2.5719473
A45: AE | B45: =B3 -> 2217080 | C45: =C3 -> 2112834 | D45: =D3 -> 1991860
A46: CMPC (WACC) | B46: 0.061 | C46: 0.065 | D46: 0.07
A47: RAE | B47: =B28 -> 0.025764068 | C47: =C28 -> 0.016768473 | D47: =D28 -> 0.0072736036
...

Sheet Question 3 
A1: Ratios de solvabilité
B2: 2021 | C2: 2022 | D2: 2023
A3: Actif circulant | B3: ='Questions 1, 2'!B8 -> 1009011 | C3: ='Questions 1, 2'!C8 -> 977309 | D3: ='Questions 1, 2'!D8 -> 993787
A4: Passif circulant | B4: ='Questions 1, 2'!B9 -> 837104 | C4: ='Questions 1, 2'!C9 -> 786993 | D4: ='Questions 1, 2'!D9 -> 796898
A5: Taux de solvabilité | B5: =B3/B4 -> 1.2053592 | C5: =C3/C4 -> 1.2418268 | D5: =D3/D4 -> 1.2470693
B8: 2021 | C8: 2022 | D8: 2023
A9: Disponibilité | B9: =Ratios!B22 -> 4634 | C9: =Ratios!C22 -> 121104 | D9: =Ratios!D22 -> 8988
A10: Passif circulant | B10: =B4 -> 837104 | C10: =C4 -> 786993 | D10: =D4 -> 796898
A11: Taux de liquidité réduite | B11: =B9/B10 -> 0.0055357518 | C11: =C9/C10 -> 0.15388193 | D11: =D9/D10 -> 0.011278733
B13: 2021 | C13: 2022 | D13: 2023
A14: Delais client(+) | B14: =Ratios!B32 -> 43.258416 | C14: =Ratios!C32 -> 46.774717 | D14: =Ratios!D32 -> 38.031918
A15: Delais stocks(+) | B15: =Ratios!B33 -> 112.54484 | C15: =Ratios!C33 -> 101.01863 | D15: =Ratios!D33 -> 101.58991
A16: Delais fournisseur (-) | B16: =Ratios!B34 -> 87.270642 | C16: =Ratios!C34 -> 89.004375 | D16: =Ratios!D34 -> 82.145042
A17: Delais BFR (jours) | B17: =B14+B15-B16 -> 68.532613 | C17: =C14+C15-C16 -> 58.788977 | D17: =D14+D15-D16 -> 57.476791
A19: Ratios d’autonomie
B20: 2021 | C20: 2022 | D20: 2023
A21: Dette Financiere | B21: =Ratios!B21 -> 496268 | C21: =Ratios!C21 -> 338125 | D21: =Ratios!D21 -> 296947
A22: Capitaux propres | B22: =Ratios!B4 -> 739784 | C22: =Ratios!C4 -> 852406 | D22: =Ratios!D4 -> 774456
A23: Taux d'endettement | B23: =B21/B22 -> 0.67082824 | C23: =C21/C22 -> 0.3966713 | D23: =D21/D22 -> 0.38342656
B25: 2021 | C25: 2022 | D25: 2023
A26: Charge financiere | B26: =Ratios!B23 -> 2097 | C26: =Ratios!C23 -> 3016 | D26: =Ratios!D23 -> 4634
A27: EBE | B27: =Ratios!B19 -> -2031 | C27: =Ratios!C19 -> -2120 | D27: =Ratios!D19 -> -1462
A28: Poids des interets | B28: =B26/B27 -> -1.0324963 | C28: =C26/C27 -> -1.4226415 | D28: =D26/D27 -> -3.1696306
B31: 2021 | C31: 2022 | D31: 2023
A32: Charge financiere | B32: =B26 -> 2097 | C32: =C26 -> 3016 | D32: =D26 -> 4634
A33: Dettes financieres | B33: =B21 -> 496268 | C33: =C21 -> 338125 | D33: =D21 -> 296947
A34: Cout de la dette | B34: =B32/B33 -> 0.0042255394 | C34: =C32/C33 -> 0.0089197782 | D34: =D32/D33 -> 0.015605478
B37: 2021 | C37: 2022 | D37: 2023
A38: CAF | B38: =B51 -> 30360 | C38: =C51 -> 28110 | D38: =D51 -> 28813
A39: Montant des investissements | B39: -108052 | C39: 277925 | D39: -69157 | F39: <---------------- lu dans "Flux de trésorerie liés aux activités d’investissement"
A40: Capacité de remboursement | B40: =B38/B39 -> -0.28097583 | C40: =C38/C39 -> 0.10114239 | D40: =D38/D39 -> -0.41663172
A42: Normes bancaires
B43: 2021 | C43: 2022 | D43: 2023
A44: Montant des dettes | B44: =Ratios!B16 -> 120230 | C44: =Ratios!C16 -> 113574 | D44: =Ratios!D16 -> 87708
A45: Total passif | B45: ='Question 5 Bilan'!J40 -> 2217080 | C45: ='Question 5 Bilan'!I40 -> 2112834 | D45: ='Question 5 Bilan'!H40 -> 1991860
A46: Norme sur les dettes | B46: =B44/B45 -> 0.054228986 | C46: =C44/C45 -> 0.053754341 | D46: =D44/D45 -> 0.044033215
B49: 2021 | C49: 2022 | D49: 2023
A50: Dettes financieres | B50: =B33 -> 496268 | C50: =C33 -> 338125 | D50: =D33 -> 296947
A51: Capacité d'autofinancement | B51: ='Questions 1, 2'!B25 -> 30360 | C51: ='Questions 1, 2'!C25 -> 28110 | D51: ='Questions 1, 2'!D25 -> 28813
A52: Norme sur la capacité de remboursement | B52: =B50/B51 -> 16.346113 | C52: =C50/C51 -> 12.028638 | D52: =D50/D51 -> 10.306008

Sheet Question 5 Bilan
C1: BILAN CONSOLIDE EN MILLIERS D'EUROS
C8: ACTIF | D8: 45107 | E8: 44742 | F8: 44377 | G8: PASSIF | H8: 45107 | I8: 44742 | J8: 44377
A9: Emplois Stables | C9: Actif immobilisé | K9: Ressources Stables
C10: Immobilisations incorporelles : | G10: Capital | H10: 57103 | I10: 57103 | J10: 57103
C11: Goodwill | D11: 384336 | E11: 400188 | F11: 468235 | G11: Primes | H11: 40103 | I11: 40101 | J11: 40103
C12: Autres immobilisations incorporelles | D12: 51733 | E12: 55721 | F12: 62381
G13: Réserves consolidées | H13: 677256 | I13: 755206 | J13: 642562
C14: Immobilisations corporelles : | D14: 369154 | E14: 372082 | F14: 535619
G15: Capitaux propres (Part du Groupe) | H15: =H13+H11+H10 -> 774462 | I15: =I13+I11+I10 -> 852410 | J15: =J13+J11+J10 -> 739768
C16: Droits utilisation | D16: 65402 | E16: 79444 | F16: 83492
C17: Titres mis en équivalence | D17: 94957 | E17: 84323 | F17: 5405 | G17: Patricipations ne donnant pas le contrôle | H17: =H18-H15 -> -6 | I17: =I18-I15 -> -4 | J17: =J18-J15 -> 16
C18: Autres actifs financiers non courants | D18: 5360 | E18: 3287 | F18: 13520 | G18: Total I | H18: 774456 | I18: 852406 | J18: 739784
C19: Autres actifs non courants | D19: 5712 | E19: 4187 | F19: 3171
G20: Passif non courant
G21: Provisions | H21: 9405 | I21: 9178 | J21: 10442
C22: Actifs d’impôts différés | D22: 12412 | E22: 15029 | F22: 31352 | G22: Engagements envers le personnel | H22: 21688 | I22: 20855 | J22: 29641
G23: Dettes financières | H23: 296947 | I23: 338125 | J23: 496268
C24: Total I | D24: =D11+D12+D14+D16+D17+D18+D19+D22 -> 989066 | E24: =E11+E12+E14+E16+E17+E18+E19+E22 -> 1014261 | F24: =F11+F12+F14+F16+F17+F18+F19+F22 -> 1203175 | G24: Passif d'impôts différés | H24: 3437 | I24: 3045 | J24: 11373
G25: Dettes location | H25: 62475 | I25: 76336 | J25: 67029
G26: Autres passifs non courants | H26: 26554 | I26: 25896 | J26: 25439
A27: Actifs Circulants | C27: Actif Courant | G27: Total II | H27: =H26+H25+H24+H23+H22+H21 -> 420506 | I27: =I26+I25+I24+I23+I22+I21 -> 473435 | J27: =J26+J25+J24+J23+J22+J21 -> 640192
C28: Stocks et en cours : | G28: Passif Courant | K28: Passifs Circulants
D29: 668080 | E29: 618296 | F29: 677057 | G29: Dettes financières courantes | H29: 75183 | I29: 60102 | J29: 150245
C30: Créances d'exploitation : | G30: Dettes de location courantes | H30: 16912 | I30: 18738 | J30: 17997
C31: Clients et comptes rattachés | D31: 305044 | E31: 343422 | F31: 311982 | G31: Provisions courantes | H31: 10524 | I31: 5033 | J31: 6625
C32: Autres | D32: 6260 | E32: 1914 | F32: 7952 | G32: Fournisseurs et autres créditeurs | H32: 687143 | I32: 690571 | J32: 653555
C33: Créances diverses | D33: 11021 | E33: 5887 | F33: 8783 | G33: Dettes d'impot | H33: 6643 | I33: 12127 | J33: 6337
G34: Autres passifs courants | H34: 493 | I34: 422 | J34: 2345
C35: Actif d'impôt courant | D35: 3382 | E35: 7790 | F35: 3237 | G35: Total III | H35: =H34+H33+H32+H31+H30+H29 -> 796898 | I35: =I34+I33+I32+I31+I30+I29 -> 786993 | J35: =J34+J33+J32+J31+J30+J29 -> 837104
A36: Trésorerie | C36: Trésorerie et équivalents de trésorerie | D36: 9007 | E36: 121264 | F36: 4894
C37: Total II | D37: =D29+D31+D32+D33+D35+D36 -> 1002794 | E37: =E36+E35+E33+E32+E31+E29 -> 1098573 | F37: =F36+F35+F32+F33+F31+F29 -> 1013905
C38: Actifs classés comme détenus en vue de la vente | D38: 0 | E38: 0 | F38: 200
C39: Ch à rép + Prime de remb + écart de conv | D39: 0 | E39: 0 | F39: 0
C40: TOTAL GENERAL | D40: =D24+D37 -> 1991860 | E40: =E24+E37 -> 2112834 | F40: =F24+F37 -> 2217080 | G40: TOTAL GENERAL | H40: =H35+H27+H18 -> 1991860 | I40: =I35+I27+I18 -> 2112834 | J40: =J35+J27+J18 -> 2217080

Sheet Question 6 Cours Moyen
A1: Date | B1: Adj Close | C1: Volume
A2: 44928 | B2: 12.996069 | C2: 7757
A3: 44929 | B3: 13.191499 | C3: 12405 | E3: Moyenne 2023:
A4: 44930 | B4: 13.386929 | C4: 18168 | E4: =AVERAGE(B2:B773) -> 11.285562
A5: 44931 | B5: 13.26967 | C5: 4342
A6: 44932 | B6: 13.211042 | C6: 5404
A7: 44935 | B7: 13.230585 | C7: 11223
A8: 44936 | B8: 13.289214 | C8: 2590 | E8: Hypothèses (CMPC) :
A9: 44937 | B9: 13.289214 | C9: 10325 | E9: Rd | F9: Bêta | G9: Rm | H9: Rf | I9: taux d'imposition IS
A10: 44938 | B10: 13.347842 | C10: 6645 | E10: 0.016 | F10: 0.5 | G10: 0.1118 | H10: 0.0281 | I10: 0.25
A11: 44939 | B11: 13.777788 | C11: 26299
A12: 44942 | B12: 14.070931 | C12: 16225 | E12: Rcp
A13: 44943 | B13: 13.621444 | C13: 21287 | E13: =H10+F10*(G10-H10) -> 0.06995
A14: 44944 | B14: 13.543272 | C14: 12898
A15: 44945 | B15: 13.171955 | C15: 16958 | E15: D/ (D + CP) | F15: CP / (CP+D) | G15: 1-τ
A16: 44946 | B16: 12.898355 | C16: 6840 | E16: =Ratios!D16/(Ratios!D16+Ratios!D4) -> 0.10173007 | F16: =Ratios!D4/(Ratios!D4+Ratios!D16) -> 0.89826993 | G16: =1-I10 -> 0.75
A17: 44949 | B17: 12.566124 | C17: 29590
A18: 44950 | B18: 12.429323 | C18: 14862 | E18: CMPC
A19: 44951 | B19: 12.487952 | C19: 8377 | E19: =F16*E13+E16*E10*G16 -> 0.064054743
A20: 44952 | B20: 12.448866 | C20: 8319
A21: 44953 | B21: 12.605209 | C21: 6578
A22: 44956 | B22: 12.175264 | C22: 16145
A23: 44957 | B23: 12.058007 | C23: 12500
A24: 44958 | B24: 12.585667 | C24: 10309
A25: 44959 | B25: 12.487952 | C25: 16130
A26: 44960 | B26: 12.487952 | C26: 11379
A27: 44963 | B27: 12.624753 | C27: 17979
A28: 44964 | B28: 13.074241 | C28: 21934
A29: 44965 | B29: 12.878812 | C29: 17801
A30: 44966 | B30: 13.074241 | C30: 7474
A31: 44967 | B31: 12.976526 | C31: 16245
... A256: 45289 | B256: 10.69 | C256: 14480

Sheet Question 6  Valeur de lentrepri
B2: 2021 | C2: 2022 | D2: 2023
A3: Flux de trésorerie d'exploitation | B3: 133728000 | C3: 123167000 | D3: 2931000
A4: Flux de trésorerie d'investissement | B4: -108052000 | C4: 277925000 | D4: -69157000
A5: Flux de trésorerie disponible | B5: =B3+B4 -> 25676000 | C5: =C3+C4 -> 401092000 | D5: =D3+D4 -> -66226000 | E5: Moyenne | F5: =AVERAGE(B5:D5) -> 1.2018067e+08
E6: Taux d'actualisation | F6: 0.064
A7: Flux de trésorerie actualisés | B7: 2024 | C7: 2025 | D7: 2026
B8: =F5/(1+F6) -> 1.1295175e+08 | C8: =F5/((1+F6)^2) -> 1.0615766e+08 | D8: =F5/((1+F6)^3) -> 99772240
A10: Valeur entreprise | B10: =B8+C8+D8 -> 3.1888166e+08

Sheet Question 7 Gordon Shapiro
B2: D0 | C2: 0.25
B3: D1 | C3: 0.29
B4: D2 | C4: 0.33
B6: g | C6: =SQRT(C4/C2)-1 -> 0.14891253
B8: r | C8: 0.17
B10: V | C10: =C3/(C8-C6) -> 13.752242
B12: Volume action | C12: 609569
B13: Valeur entreprise | C13: =C10*C12 -> 8382940.4
G16: Source : Boursorama

Sheet Question 7 Feltham Olson
A1: Estimation d'un modèle linéaire
B3: 2019 | C3: 2020 | D3: 2021 | E3: 2022 | F3: 2023
A4: Bénéfice d'exploitation oxt | B4: -2598 | C4: -2612 | D4: =Ratios!B19 -> -2031 | E4: =Ratios!C19 -> -2120 | F4: =Ratios!D19 -> -1462
A5: Actif exploitation net oat | B5: =57098+481881+527614+627426+324163+4392+11883 -> 2034457 | C5: =58478+483183+523618+627128+311075+9004+8336 -> 2020822 | D5: ='Question 5 Bilan'!F11+'Question 5 Bilan'!F12+'Question 5 Bilan'!F14+'Question 5 Bilan'!F29+'Question 5 Bilan'!F31+'Question 5 Bilan'!F32+'Question 5 Bilan'!F33 -> 2072009 | E5: ='Question 5 Bilan'!E11+'Question 5 Bilan'!E12+'Question 5 Bilan'!E14+'Question 5 Bilan'!E29+'Question 5 Bilan'!E31+'Question 5 Bilan'!E32+'Question 5 Bilan'!E33 -> 1797510 | F5: ='Question 5 Bilan'!D11+'Question 5 Bilan'!D12+'Question 5 Bilan'!D14+'Question 5 Bilan'!D29+'Question 5 Bilan'!D31+'Question 5 Bilan'!D32+'Question 5 Bilan'!D33 -> 1795628
A6: Bénéfice résiduel d'exploitation oxat | C6: =C4-$C9*B5 -> -59780.242 | D6: =D4-$C9*C5 -> -58816.098 | E6: =E4-$C9*D5 -> -60343.453 | F6: =F4-$C9*E5 -> -51972.031
B9: R-1 | C9: 0.0281
B10: Book Value | C10: =Ratios!D4 -> 774456
A18: Régression oat | B18: Constante | C18: oat-1
B19: 1148000 | C19: -0.3769
A21: Régression FO | B21: Constante | C21: oxat-1 | D21: oat
B22: -357200 | C22: -5.464 | D22: -0.01363
A30: En faisant 2 régressions distinctes
D31: oxat/oxat-1 | E31: oxat/oat-1
B32: Pente | D32: -5.06 | E32: -0.03054
B33: Ordonnée à l'origine | D33: -358867.22 | E33: 2924.65728
D38: Non concluant au vu des conditions sur les coefficients | E38: Pt
E39: =C10+C6+(1/(1+C9))*D6+(1/((1+C9)^2))*E6+(1/((1+C9)^3))*F6 -> 552551.35
A44: Somme actualisée des dividendes
C45: Dividendes calculés avec g | D45: Dividendes calculés avec R
B46: 0 | C46: ='Question 7 Gordon Shapiro'!C2 -> 0.25 | D46: =C46/((1+C$9)^C46) -> 0.24827396
B47: 1 | C47: =C46*(1+'Question 7 Gordon Shapiro'!C$6) -> 0.28722813 | D47: =C47/((1+C$9)^C47) -> 0.28495093
B48: 2 | C48: =C47*(1+'Question 7 Gordon Shapiro'!C$6) -> 0.33 | D48: =C48/((1+C$9)^C48) -> 0.32699587
B49: 3 | C49: =C48*(1+'Question 7 Gordon Shapiro'!C$6) -> 0.37914113 | D49: =C49/((1+C$9)^C49) -> 0.37517838
B50: 4 | C50: =C49*(1+'Question 7 Gordon Shapiro'!C$6) -> 0.4356 | D50: =C50/((1+C$9)^C50) -> 0.43037325
B51: 5 | C51: =C50*(1+'Question 7 Gordon Shapiro'!C$6) -> 0.5004663 | D51: =C51/((1+C$9)^C51) -> 0.49357317
B52: 6 | C52: =C51*(1+'Question 7 Gordon Shapiro'!C$6) -> 0.574992 | D52: =C52/((1+C$9)^C52) -> 0.56590244
B53: 7 | C53: =C52*(1+'Question 7 Gordon Shapiro'!C$6) -> 0.66061551 | D53: =C53/((1+C$9)^C53) -> 0.64863148 | F53: Prix (5) | G53: =SUM(D46:D51) -> 2.1593456
B54: 8 | C54: =C53*(1+'Question 7 Gordon Shapiro'!C$6) -> 0.75898944 | D54: =C54/((1+C$9)^C54) -> 0.74319199
B55: 9 | C55: =C54*(1+'Question 7 Gordon Shapiro'!C$6) -> 0.87201248 | D55: =C55/((1+C$9)^C55) -> 0.85119236
B56: 10 | C56: =C55*(1+'Question 7 Gordon Shapiro'!C$6) -> 1.0018661 | D56: =C56/((1+C$9)^C56) -> 0.97443269 | F56: Prix (10) | G56: =SUM(D46:D56) -> 5.9426965
